Workbook

Sheet گزارش تجمیعی
A1: داشبورد تجمیعی ۱۲ هفته محتوا — نوتوپیا
A2: این داشبورد به‌صورت خودکار از شیت‌های هفته ۱ تا ۱۲ داده می‌خواند. فقط آمار هر هفته را در شیت مربوطه پر کنید.
A4: اهداف ۳ ماهه و وضعیت پیشرفت
A5: هدف | B5: شرح | C5: نوع | D5: وضعیت دستی | E5: یادداشت
A6: ۱. وضوح محصول برای گروه B | B6: حداقل ۷۰٪ محتوا به سوالات کاربرد/تفاوت/نحوه کار جواب دهد | C6: هدف کیفی
A7: ۲. دارایی پشتیبانی فروش | B7: ۳ Case Study + ۴ پاسخ اعتراض + ۲ ویدئوی کوتاه | C7: هدف کمی
A8: ۳. آماده‌سازی فصل هدیه | B8: از هفته ۸ به بعد ≥۵۰٪ محتوا حول هدیه سازمانی | C8: هدف کیفی
A9: ۴. نمایش مدل‌های فیزیکی | B9: نمایش منظم رنگ/جلد/مدل و شخصی‌سازی | C9: هدف کیفی
A10: ۵. نظم اجرا و ثبت آمار | B10: هر ۱۲ هفته آمار ثبت‌شده + وضعیت اجرا مشخص | C10: هدف فرآیندی
A12: وضعیت اجرای هفته‌ها (خوانده‌شده از شیت‌های هفتگی)
A13: هفته | B13: موضوع محوری | C13: وضعیت اجرا | D13: بازدید کل | E13: تعامل کل | F13: نرخ تعامل % | G13: کلیک کل | H13: پیام ورودی | I13: تعداد محتوا | J13: پیشرفت % | K13: وضعیت رنگی
A14: 1 | B14: نوتوپیا به چه دردی می‌خورد؟ | C14: ='هفته 1'!B12 -> انجام‌شده | D14: =IF('هفته 1'!B21="","",'هفته 1'!B21) -> 0 | E14: =IF('هفته 1'!C21="","",'هفته 1'!C21) -> 0 | F14: =IF(OR(D14="",D14=0),"",ROUND(E14/D14*100,1)) | G14: =IF('هفته 1'!E21="","",'هفته 1'!E21) -> 0 | H14: =IF('هفته 1'!F21="","",'هفته 1'!F21) -> 0 | I14: 3 | J14: =IF(C14="انجام‌شده",100,IF(C14="ناقص",50,IF(C14="انجام‌نشده",0,""))) -> 100 | K14: =IF(C14="انجام‌شده","✅ کامل",IF(C14="ناقص","⚠️ ناقص",IF(C14="انجام‌نشده","❌ نشده",""))) -> ✅ کامل
A15: 2 | B15: چطور کار می‌کند؟ (نسخه ساده) | C15: ='هفته 2'!B12 -> 0 | D15: =IF('هفته 2'!B21="","",'هفته 2'!B21) -> 0 | E15: =IF('هفته 2'!C21="","",'هفته 2'!C21) -> 0 | F15: =IF(OR(D15="",D15=0),"",ROUND(E15/D15*100,1)) | G15: =IF('هفته 2'!E21="","",'هفته 2'!E21) -> 0 | H15: =IF('هفته 2'!F21="","",'هفته 2'!F21) -> 0 | I15: 3 | J15: =IF(C15="انجام‌شده",100,IF(C15="ناقص",50,IF(C15="انجام‌نشده",0,""))) | K15: =IF(C15="انجام‌شده","✅ کامل",IF(C15="ناقص","⚠️ ناقص",IF(C15="انجام‌نشده","❌ نشده","")))
A16: 3 | B16: تفاوت با دفتر و سررسید معمولی | C16: ='هفته 3'!B12 -> 0 | D16: =IF('هفته 3'!B21="","",'هفته 3'!B21) -> 0 | E16: =IF('هفته 3'!C21="","",'هفته 3'!C21) -> 0 | F16: =IF(OR(D16="",D16=0),"",ROUND(E16/D16*100,1)) | G16: =IF('هفته 3'!E21="","",'هفته 3'!E21) -> 0 | H16: =IF('هفته 3'!F21="","",'هفته 3'!F21) -> 0 | I16: 3 | J16: =IF(C16="انجام‌شده",100,IF(C16="ناقص",50,IF(C16="انجام‌نشده",0,""))) | K16: =IF(C16="انجام‌شده","✅ کامل",IF(C16="ناقص","⚠️ ناقص",IF(C16="انجام‌نشده","❌ نشده","")))
A17: 4 | B17: معرفی مدل‌های فیزیکی (بخش ۱) | C17: ='هفته 4'!B12 -> 0 | D17: =IF('هفته 4'!B21="","",'هفته 4'!B21) -> 0 | E17: =IF('هفته 4'!C21="","",'هفته 4'!C21) -> 0 | F17: =IF(OR(D17="",D17=0),"",ROUND(E17/D17*100,1)) | G17: =IF('هفته 4'!E21="","",'هفته 4'!E21) -> 0 | H17: =IF('هفته 4'!F21="","",'هفته 4'!F21) -> 0 | I17: 3 | J17: =IF(C17="انجام‌شده",100,IF(C17="ناقص",50,IF(C17="انجام‌نشده",0,""))) | K17: =IF(C17="انجام‌شده","✅ کامل",IF(C17="ناقص","⚠️ ناقص",IF(C17="انجام‌نشده","❌ نشده","")))
A18: 5 | B18: پاسخ به اعتراض رایج قیمت | C18: ='هفته 5'!B12 -> 0 | D18: =IF('هفته 5'!B21="","",'هفته 5'!B21) -> 0 | E18: =IF('هفته 5'!C21="","",'هفته 5'!C21) -> 0 | F18: =IF(OR(D18="",D18=0),"",ROUND(E18/D18*100,1)) | G18: =IF('هفته 5'!E21="","",'هفته 5'!E21) -> 0 | H18: =IF('هفته 5'!F21="","",'هفته 5'!F21) -> 0 | I18: 3 | J18: =IF(C18="انجام‌شده",100,IF(C18="ناقص",50,IF(C18="انجام‌نشده",0,""))) | K18: =IF(C18="انجام‌شده","✅ کامل",IF(C18="ناقص","⚠️ ناقص",IF(C18="انجام‌نشده","❌ نشده","")))
A19: 6 | B19: Case Study شماره ۱ (روایت داخلی) | C19: ='هفته 6'!B12 -> 0 | D19: =IF('هفته 6'!B21="","",'هفته 6'!B21) -> 0 | E19: =IF('هفته 6'!C21="","",'هفته 6'!C21) -> 0 | F19: =IF(OR(D19="",D19=0),"",ROUND(E19/D19*100,1)) | G19: =IF('هفته 6'!E21="","",'هفته 6'!E21) -> 0 | H19: =IF('هفته 6'!F21="","",'هفته 6'!F21) -> 0 | I19: 3 | J19: =IF(C19="انجام‌شده",100,IF(C19="ناقص",50,IF(C19="انجام‌نشده",0,""))) | K19: =IF(C19="انجام‌شده","✅ کامل",IF(C19="ناقص","⚠️ ناقص",IF(C19="انجام‌نشده","❌ نشده","")))
A20: 7 | B20: مدل‌های فیزیکی (بخش ۲) + شخصی‌سازی | C20: ='هفته 7'!B12 -> 0 | D20: =IF('هفته 7'!B21="","",'هفته 7'!B21) -> 0 | E20: =IF('هفته 7'!C21="","",'هفته 7'!C21) -> 0 | F20: =IF(OR(D20="",D20=0),"",ROUND(E20/D20*100,1)) | G20: =IF('هفته 7'!E21="","",'هفته 7'!E21) -> 0 | H20: =IF('هفته 7'!F21="","",'هفته 7'!F21) -> 0 | I20: 3 | J20: =IF(C20="انجام‌شده",100,IF(C20="ناقص",50,IF(C20="انجام‌نشده",0,""))) | K20: =IF(C20="انجام‌شده","✅ کامل",IF(C20="ناقص","⚠️ ناقص",IF(C20="انجام‌نشده","❌ نشده","")))
A21: 8 | B21: هدیه سازمانی چیست و چرا مهم است؟ | C21: ='هفته 8'!B12 -> 0 | D21: =IF('هفته 8'!B21="","",'هفته 8'!B21) -> 0 | E21: =IF('هفته 8'!C21="","",'هفته 8'!C21) -> 0 | F21: =IF(OR(D21="",D21=0),"",ROUND(E21/D21*100,1)) | G21: =IF('هفته 8'!E21="","",'هفته 8'!E21) -> 0 | H21: =IF('هفته 8'!F21="","",'هفته 8'!F21) -> 0 | I21: 3 | J21: =IF(C21="انجام‌شده",100,IF(C21="ناقص",50,IF(C21="انجام‌نشده",0,""))) | K21: =IF(C21="انجام‌شده","✅ کامل",IF(C21="ناقص","⚠️ ناقص",IF(C21="انجام‌نشده","❌ نشده","")))
A22: 9 | B22: تجربه گیرنده هدیه | C22: ='هفته 9'!B12 -> 0 | D22: =IF('هفته 9'!B21="","",'هفته 9'!B21) -> 0 | E22: =IF('هفته 9'!C21="","",'هفته 9'!C21) -> 0 | F22: =IF(OR(D22="",D22=0),"",ROUND(E22/D22*100,1)) | G22: =IF('هفته 9'!E21="","",'هفته 9'!E21) -> 0 | H22: =IF('هفته 9'!F21="","",'هفته 9'!F21) -> 0 | I22: 3 | J22: =IF(C22="انجام‌شده",100,IF(C22="ناقص",50,IF(C22="انجام‌نشده",0,""))) | K22: =IF(C22="انجام‌شده","✅ کامل",IF(C22="ناقص","⚠️ ناقص",IF(C22="انجام‌نشده","❌ نشده","")))
A23: 10 | B23: Case Study ۲ + زمان‌بندی خرید | C23: ='هفته 10'!B12 -> 0 | D23: =IF('هفته 10'!B21="","",'هفته 10'!B21) -> 0 | E23: =IF('هفته 10'!C21="","",'هفته 10'!C21) -> 0 | F23: =IF(OR(D23="",D23=0),"",ROUND(E23/D23*100,1)) | G23: =IF('هفته 10'!E21="","",'هفته 10'!E21) -> 0 | H23: =IF('هفته 10'!F21="","",'هفته 10'!F21) -> 0 | I23: 3 | J23: =IF(C23="انجام‌شده",100,IF(C23="ناقص",50,IF(C23="انجام‌نشده",0,""))) | K23: =IF(C23="انجام‌شده","✅ کامل",IF(C23="ناقص","⚠️ ناقص",IF(C23="انجام‌نشده","❌ نشده","")))
A24: 11 | B24: پاسخ به اعتراض زمان تحویل و تیراژ | C24: ='هفته 11'!B12 -> 0 | D24: =IF('هفته 11'!B21="","",'هفته 11'!B21) -> 0 | E24: =IF('هفته 11'!C21="","",'هفته 11'!C21) -> 0 | F24: =IF(OR(D24="",D24=0),"",ROUND(E24/D24*100,1)) | G24: =IF('هفته 11'!E21="","",'هفته 11'!E21) -> 0 | H24: =IF('هفته 11'!F21="","",'هفته 11'!F21) -> 0 | I24: 3 | J24: =IF(C24="انجام‌شده",100,IF(C24="ناقص",50,IF(C24="انجام‌نشده",0,""))) | K24: =IF(C24="انجام‌شده","✅ کامل",IF(C24="ناقص","⚠️ ناقص",IF(C24="انجام‌نشده","❌ نشده","")))
A25: 12 | B25: جمع‌بندی + دعوت ملایم | C25: ='هفته 12'!B12 -> 0 | D25: =IF('هفته 12'!B21="","",'هفته 12'!B21) -> 0 | E25: =IF('هفته 12'!C21="","",'هفته 12'!C21) -> 0 | F25: =IF(OR(D25="",D25=0),"",ROUND(E25/D25*100,1)) | G25: =IF('هفته 12'!E21="","",'هفته 12'!E21) -> 0 | H25: =IF('هفته 12'!F21="","",'هفته 12'!F21) -> 0 | I25: 3 | J25: =IF(C25="انجام‌شده",100,IF(C25="ناقص",50,IF(C25="انجام‌نشده",0,""))) | K25: =IF(C25="انجام‌شده","✅ کامل",IF(C25="ناقص","⚠️ ناقص",IF(C25="انجام‌نشده","❌ نشده","")))
A26: جمع / میانگین | C26: =COUNTIF(C14:C25,"انجام‌شده")&" از ۱۲" -> 1 از ۱۲ | D26: =SUM(D14:D25) -> 0 | E26: =SUM(E14:E25) -> 0 | F26: =IF(D26=0,"",ROUND(E26/D26*100,1)) | G26: =SUM(G14:G25) -> 0 | H26: =SUM(H14:H25) -> 0 | I26: =SUM(I14:I25) -> 36 | J26: =IF(COUNT(J14:J25)=0,"",ROUND(AVERAGE(J14:J25),0)) -> 100
A28: شاخص‌های کلیدی عملکرد (KPI)
A29: درصد پیشرفت کلی برنامه | C29: =IF(COUNT(J14:J25)=0,"—",ROUND(AVERAGE(J14:J25),0)&"%") -> 100%
A30: تعداد هفته‌های تکمیل‌شده | C30: =COUNTIF(C14:C25,"انجام‌شده")&" از ۱۲" -> 1 از ۱۲
A31: مجموع بازدید ثبت‌شده | C31: =IF(D26=0,"—",TEXT(D26,"#,##0")) -> —
A32: مجموع تعامل ثبت‌شده | C32: =IF(E26=0,"—",TEXT(E26,"#,##0")) -> —
A33: میانگین نرخ تعامل | C33: =IF(F26="","—",F26) -> —
A34: مجموع پیام ورودی | C34: =IF(H26=0,"—",TEXT(H26,"#,##0")) -> —
A36: چک‌لیست دارایی‌های پشتیبانی فروش (دستی به‌روز کنید)
A37: دارایی | B37: وضعیت | C37: هفته مرتبط | D37: لینک / محل فایل | E37: یادداشت
A38: Case Study شماره ۱ | C38: هفته ۶
A39: Case Study شماره ۲ | C39: هفته ۱۰
A40: Case Study شماره ۳ | C40: —
A41: ویدئوی «چطور کار می‌کند» | C41: هفته ۲
A42: ویدئوی تجربه گیرنده / دوم | C42: هفته ۹
A43: پاسخ اعتراض قیمت | C43: هفته ۵
A44: پاسخ اعتراض زمان تحویل | C44: هفته ۱۱
...

Sheet راهنمای استفاده
A1: راهنمای استفاده از فایل نقشه راه ۱۲ هفته محتوا — نوتوپیا
A3: ساختار فایل:
A4: • شیت «گزارش تجمیعی»: داشبورد زنده که از شیت‌های هفتگی داده می‌خواند + اهداف + چک‌لیست دارایی‌ها
A5: • شیت‌های «هفته ۱» تا «هفته ۱۲»: جزئیات کامل کارها + محل ثبت آمار هر هفته
A6: • شیت «راهنمای استفاده»: همین توضیحات
A8: نحوه کار تیم:
A9: ۱. در ابتدای هر هفته شیت مربوط به همان هفته را باز کنید.
A10: ۲. هدف هفته را بخوانید.
A11: ۳. کارهای شماره‌گذاری‌شده را دقیقاً طبق «قدم‌ها و جزئیات دقیق اجرا» انجام دهید.
A12: ۴. از کپشن و متن پیشنهادی استفاده کنید (قابل ویرایش جزئی در حد لحن).
A13: ۵. بعد از انتشار، بخش «ثبت نتایج و آمار» را پر کنید و وضعیت اجرا را از لیست کشویی انتخاب کنید.
A14: ۶. داشبورد تجمیعی به‌صورت خودکار به‌روز می‌شود.
... A28: • نکته کیفی: هر مشاهده مهم (مثلاً کامنت پرتکرار یا سوال جدید)

Sheet هفته 1
A1: هفته 1 — نوتوپیا به چه دردی می‌خورد؟
A2: هدف هفته: مخاطب گروه B بفهمد این محصول برای چه موقعیت‌هایی ساخته شده و چرا از سررسید معمولی بهتر است.
A4: شماره | B4: عنوان کار | C4: نوع محتوا | D4: کانال‌ها | E4: قدم‌ها و جزئیات دقیق اجرا | F4: کپشن / متن پیشنهادی | G4: خروجی مورد انتظار
A5: 1 | B5: پست اصلی کاروسل: ۳ موقعیتی که سررسید معمولی کم می‌آورد | C5: پست کاروسل (۳ اسلاید) | D5: اینستاگرام + لینکدین + سایت | E5: اسلاید ۱: عنوان بزرگ «سررسید معمولی این ۳ جا کم می‌آورد» زیرعنوان: هدیه به مشتری مهم | هدیه کارکنان | ثبت تصمیمات جلسات مدیریتی اسلاید ۲: برای هر موقعیت یک جمله مشکل + یک جمله راه‌حل: • هدیه مشتری مهم → مشکل: زود فراموش می‌شود. راه‌حل: با واقعیت افزوده برند شما زنده می‌ماند. • هدیه کارکنان → مشکل: بعد چند ماه تبدیل به دفتر معمولی می‌شود. راه‌حل: نوشته‌ها اسکن و قابل جستجو می‌شوند. • جلسات مدیریتی → مشکل: ایده‌ها گم می‌شوند. راه‌حل: با علامت‌زدن و اسکن، همه چیز منظم می‌ماند. اسلاید ۳: تصویر محصول + جمله «نوتوپیا فقط یک سررسید نیست. هدیه‌ای است که کار می‌کند.» | F5: خیلی از سازمان‌ها هنوز برای هدیه سازمانی همان سررسید معمولی را می‌خرند. اما سه جا این انتخاب ضعیف عمل می‌کند: ۱. وقتی می‌خواهید مشتری مهم‌تان شما را فراموش نکند ۲. وقتی می‌خواهید کارکنان واقعاً از هدیه استفاده کنند ۳. وقتی ایده‌ها و تصمیمات جلسات نباید گم شوند نوتوپیا برای همین سه موقعیت ساخته شده. در کامنت بنویسید کدام موقعیت برای سازمان شما مهم‌تر است. | G5: ۱ پست کاروسل ۳ اسلایدی
A6: 2 | B6: استوری سریالی ۴ فریمی | C6: استوری | D6: اینستاگرام + پیام‌رسان‌ها | E6: فریم ۱: «تا حالا هدیه‌ای دادید که بعد از دو ماه کسی سراغش را نگیرد؟» فریم ۲: «سررسید معمولی معمولاً همین‌طور تمام می‌شود.» فریم ۳: «نوتوپیا طوری طراحی شده که هم روی میز بماند و هم در گوشی قابل استفاده باشد.» فریم ۴: «پست امروز را ببینید ← سه موقعیتی که این تفاوت مهم می‌شود» | F6: — | G6: ۱ سری استوری ۴ فریمی
A7: 3 | B7: متن کوتاه برای پیامک/ایمیل لیست گرم | C7: پیامک / ایمیل | D7: پیامک + ایمیل | E7: متن حداکثر ۸۰ کلمه آماده ارسال. لینک پست اصلی را در انتها قرار دهید. | F7: سه موقعیتی که سررسید معمولی کم می‌آورد و نوتوپیا وارد می‌شود: هدیه به مشتری مهم، هدیه کارکنان، و ثبت تصمیمات جلسات. اگر برای سازمان‌تان یکی از این سه مورد مهم است، این پست را ببینید: [لینک] | G7: ۱ متن آماده ارسال
A9: نکات اجرایی هفته: تصاویر را می‌توان با هوش مصنوعی یا عکس موجود محصول ساخت. نیاز به فیلم‌برداری حرفه‌ای نیست.
A11: 📊 ثبت نتایج و آمار این هفته (بعد از انتشار — حتماً پر شود)
A12: وضعیت اجرا: | B12: انجام‌شده | C12: (انتخاب کنید: انجام‌شده / ناقص / انجام‌نشده)
A14: پلتفرم | B14: بازدید / Reach | C14: تعامل (لایک+کامنت+ذخیره) | D14: نرخ تعامل % | E14: کلیک / لینک | F14: پیام ورودی | G14: ذخیره / اشتراک | H14: نکته کیفی | I14: تاریخ ثبت
A15: اینستاگرام | D15: =IF(B15=0,"",IF(B15="","",ROUND(C15/B15*100,1)))
A16: لینکدین | D16: =IF(B16=0,"",IF(B16="","",ROUND(C16/B16*100,1)))
A17: سایت | D17: =IF(B17=0,"",IF(B17="","",ROUND(C17/B17*100,1)))
A18: آپارات | D18: =IF(B18=0,"",IF(B18="","",ROUND(C18/B18*100,1)))
A19: پیامک/ایمیل | D19: =IF(B19=0,"",IF(B19="","",ROUND(C19/B19*100,1)))
A20: سایر | D20: =IF(B20=0,"",IF(B20="","",ROUND(C20/B20*100,1)))
A21: جمع کل | B21: =SUM(B15:B20) -> 0 | C21: =SUM(C15:C20) -> 0 | D21: =IF(B21=0,"",IF(B21="","",ROUND(C21/B21*100,1))) | E21: =SUM(E15:E20) -> 0 | F21: =SUM(F15:F20) -> 0 | G21: =SUM(G15:G20) -> 0

Sheet هفته 2
A1: هفته 2 — چطور کار می‌کند؟ (نسخه ساده)
A2: هدف هفته: هر کسی که اولین بار می‌بیند، در کمتر از ۴۵ ثانیه بفهمد جریان کار نوتوپیا چیست.
A4: شماره | B4: عنوان کار | C4: نوع محتوا | D4: کانال‌ها | E4: قدم‌ها و جزئیات دقیق اجرا | F4: کپشن / متن پیشنهادی | G4: خروجی مورد انتظار
A5: 1 | B5: ویدئوی اصلی ۳۰–۴۵ ثانیه‌ای «از نوشتن تا دیجیتال» | C5: ریلز / ویدئو | D5: اینستاگرام + آپارات + لینکدین | E5: سناریو تصویر به تصویر: ثانیه ۰–۸: دست در حال نوشتن روی صفحه نوتوپیا با خودکار → متن روی تصویر: «بنویسید» ثانیه ۸–۱۸: انگشت در حال علامت زدن دایره‌های دسته‌بندی و تاریخ → متن: «علامت بزنید» ثانیه ۱۸–۳۲: گوشی بالای صفحه گرفته می‌شود و اسکن انجام می‌شود → متن: «اسکن کنید» ثانیه ۳۲–۴۵: صفحه اسکن‌شده داخل اپلیکیشن + جستجوی سریع → متن: «نوشته‌ها دیجیتال و قابل جستجو می‌شوند» نکات اجباری: • هیچ توضیح شفاهی طولانی نباشد. • موسیقی آرام و بدون کلام. • فیلم با گوشی قابل ضبط است. • در پایان: لوگو + جمله «نوتوپیا – اولین نوشت‌افزار هوشمند ایران» | F5: نوتوپیا در سه قدم ساده: بنویسید، علامت بزنید، اسکن کنید. بدون تغییر عادت نوشتن، همه‌چیز دیجیتال می‌شود. | G5: ۱ ویدئوی نهایی ۳۰–۴۵ ثانیه
A6: 2 | B6: پست تکمیلی کاروسل: نوتوپیا در ۳ قدم | C6: پست کاروسل | D6: اینستاگرام + لینکدین + سایت | E6: اسلاید ۱: عنوان «نوتوپیا در ۳ قدم» اسلاید ۲: قدم ۱: بنویسید (در نسخه مانا با خودکار پاک‌شونده) قدم ۲: علامت بزنید (دسته‌بندی و تاریخ) قدم ۳: اسکن کنید (اپلیکیشن صفحه را ذخیره می‌کند) اسلاید ۳: جمله نهایی «بدون تغییر عادت نوشتن، همه‌چیز دیجیتال می‌شود» | F6: سه قدم ساده. یک نتیجه هوشمند. | G6: ۱ پست کاروسل ۳ اسلایدی
A7: 3 | B7: استوری سوال متداول درباره خودکار | C7: استوری | D7: اینستاگرام | E7: فریم ۱: سوال «آیا باید خودکار خاصی استفاده کنم؟» فریم ۲: جواب «در نسخه مانا بله. از خودکار پاک‌شونده استفاده می‌شود تا بتوانید صفحه را پاک کنید و دوباره بنویسید.» فریم ۳: «این قابلیت باعث می‌شود یک دفتر را بارها استفاده کنید و همزمان همه نوشته‌ها در اپلیکیشن ذخیره بمانند.» فریم ۴: دعوت به دیدن ویدئوی اصلی | F7: — | G7: استوری ۴ فریمی
A9: نکات اجرایی هفته: نسخه مانا: خودکار پاک‌شونده یک قابلیت است (صفحات قابل استفاده مجدد)، نه نقطه ضعف. در محتوا این موضوع را مثبت و ارزش‌مند نشان دهید.
A11: 📊 ثبت نتایج و آمار این هفته (بعد از انتشار — حتماً پر شود)
A12: وضعیت اجرا: | C12: (انتخاب کنید: انجام‌شده / ناقص / انجام‌نشده)
A14: پلتفرم | B14: بازدید / Reach | C14: تعامل (لایک+کامنت+ذخیره) | D14: نرخ تعامل % | E14: کلیک / لینک | F14: پیام ورودی | G14: ذخیره / اشتراک | H14: نکته کیفی | I14: تاریخ ثبت
A15: اینستاگرام | D15: =IF(B15=0,"",IF(B15="","",ROUND(C15/B15*100,1)))
A16: لینکدین | D16: =IF(B16=0,"",IF(B16="","",ROUND(C16/B16*100,1)))
A17: سایت | D17: =IF(B17=0,"",IF(B17="","",ROUND(C17/B17*100,1)))
A18: آپارات | D18: =IF(B18=0,"",IF(B18="","",ROUND(C18/B18*100,1)))
A19: پیامک/ایمیل | D19: =IF(B19=0,"",IF(B19="","",ROUND(C19/B19*100,1)))
A20: سایر | D20: =IF(B20=0,"",IF(B20="","",ROUND(C20/B20*100,1)))
A21: جمع کل | B21: =SUM(B15:B20) -> 0 | C21: =SUM(C15:C20) -> 0 | D21: =IF(B21=0,"",IF(B21="","",ROUND(C21/B21*100,1))) | E21: =SUM(E15:E20) -> 0 | F21: =SUM(F15:F20) -> 0 | G21: =SUM(G15:G20) -> 0

Sheet هفته 3
A1: هفته 3 — تفاوت با دفتر و سررسید معمولی
A2: هدف هفته: جدا کردن واضح نوتوپیا از کالای معمولی و تثبیت جایگاه «نوشت‌افزار هوشمند».
A4: شماره | B4: عنوان کار | C4: نوع محتوا | D4: کانال‌ها | E4: قدم‌ها و جزئیات دقیق اجرا | F4: کپشن / متن پیشنهادی | G4: خروجی مورد انتظار
A5: 1 | B5: پست مقایسه‌ای شفاف | C5: پست کاروسل یا تصویری | D5: اینستاگرام + لینکدین + سایت | E5: ساختار پیشنهادی کاروسل: اسلاید ۱: عنوان «سررسید معمولی در برابر نوتوپیا» اسلاید ۲: جدول یا دو ستون مقایسه (ظاهر مشابه / قابلیت دیجیتال / استفاده مجدد صفحه / هدیه ماندگار) اسلاید ۳: جمع‌بندی یک جمله‌ای: «ظاهر یک سررسید، قابلیت یک ابزار هوشمند.» | F5: ظاهر آشنا. قابلیت متفاوت. نوتوپیا همان دفتر همیشگی است که دیگر محدود به کاغذ نمی‌ماند. | G5: ۱ پست مقایسه‌ای
A6: 2 | B6: استوری مقایسه سریع | C6: استوری | D6: اینستاگرام | E6: ۳ یا ۴ فریم: یک تفاوت در هر فریم + دعوت به پست اصلی | F6: — | G6: استوری ۳–۴ فریمی
A7: 3 | B7: متن کمکی برای فروشنده | C7: متن داخلی | D7: تیم فروش | E7: یک پاراگراف کوتاه آماده که فروشنده بتواند در جلسه یا پیام برای توضیح تفاوت استفاده کند. | F7: نوتوپیا ظاهر یک سررسید باکیفیت را دارد، اما نوشته‌ها اسکن و قابل جستجو می‌شوند و در نسخه مانا صفحات قابل استفاده مجدد هستند. این تفاوت باعث می‌شود هم به‌عنوان هدیه خاص دیده شود و هم واقعاً استفاده شود. | G7: ۱ متن استاندارد برای فروش
A9: نکات اجرایی هفته: از زبان تهاجمی علیه رقبا خودداری کنید. تمرکز روی تفاوت ارزش باشد.
A11: 📊 ثبت نتایج و آمار این هفته (بعد از انتشار — حتماً پر شود)
A12: وضعیت اجرا: | C12: (انتخاب کنید: انجام‌شده / ناقص / انجام‌نشده)
A14: پلتفرم | B14: بازدید / Reach | C14: تعامل (لایک+کامنت+ذخیره) | D14: نرخ تعامل % | E14: کلیک / لینک | F14: پیام ورودی | G14: ذخیره / اشتراک | H14: نکته کیفی | I14: تاریخ ثبت
A15: اینستاگرام | D15: =IF(B15=0,"",IF(B15="","",ROUND(C15/B15*100,1)))
A16: لینکدین | D16: =IF(B16=0,"",IF(B16="","",ROUND(C16/B16*100,1)))
A17: سایت | D17: =IF(B17=0,"",IF(B17="","",ROUND(C17/B17*100,1)))
A18: آپارات | D18: =IF(B18=0,"",IF(B18="","",ROUND(C18/B18*100,1)))
A19: پیامک/ایمیل | D19: =IF(B19=0,"",IF(B19="","",ROUND(C19/B19*100,1)))
A20: سایر | D20: =IF(B20=0,"",IF(B20="","",ROUND(C20/B20*100,1)))
A21: جمع کل | B21: =SUM(B15:B20) -> 0 | C21: =SUM(C15:C20) -> 0 | D21: =IF(B21=0,"",IF(B21="","",ROUND(C21/B21*100,1))) | E21: =SUM(E15:E20) -> 0 | F21: =SUM(F15:F20) -> 0 | G21: =SUM(G15:G20) -> 0

Sheet هفته 4
A1: هفته 4 — معرفی مدل‌های فیزیکی (بخش ۱)
A2: هدف هفته: مشتری با ظاهر، رنگ و جلد محصول راحت‌تر ارتباط بگیرد و سوالات رایج رنگ/جلد کاهش یابد.
A4: شماره | B4: عنوان کار | C4: نوع محتوا | D4: کانال‌ها | E4: قدم‌ها و جزئیات دقیق اجرا | F4: کپشن / متن پیشنهادی | G4: خروجی مورد انتظار
A5: 1 | B5: پست/ویدئو نمایش رنگ و جلد | C5: پست یا ویدئوی کوتاه | D5: اینستاگرام + لینکدین + سایت | E5: نمایش واضح مدل‌های موجود: • هر مدل با نام یا کد مشخص • رنگ و جنس جلد به وضوح دیده شود • یک جمله ارزش برای هر مدل (مثلاً حس رسمی برای مدیران / حس مدرن برای تیم‌های جوان) از عکس واقعی یا رندر باکیفیت استفاده کنید. | F5: انتخاب ظاهر، بخشی از تجربه هدیه است. مدل‌های نوتوپیا برای سلیقه‌ها و موقعیت‌های مختلف طراحی شده‌اند. | G5: ۱ پست یا ویدئوی نمایش مدل‌ها
A6: 2 | B6: استوری جزئیات فیزیکی | C6: استوری | D6: اینستاگرام | E6: فریم‌های نزدیک از جلد، لبه صفحات، کیفیت چاپ یا جزئیات لمسی (در صورت امکان) | F6: — | G6: استوری جزئیات
A7: 3 | B7: پاسخ آماده به سوال رنگ و جلد | C7: متن داخلی | D7: تیم فروش + پشتیبانی | E7: ۲–۳ پاسخ کوتاه استاندارد برای سوال‌های پرتکرار درباره رنگ، جلد و تفاوت مدل‌ها. | F7: — | G7: ۲–۳ پاسخ استاندارد
A9: نکات اجرایی هفته: قبل از انتشار، با تیم تولید فیزیکی هماهنگ کنید که مدل‌های نمایش‌داده‌شده موجود و قابل سفارش باشند.
A11: 📊 ثبت نتایج و آمار این هفته (بعد از انتشار — حتماً پر شود)
A12: وضعیت اجرا: | C12: (انتخاب کنید: انجام‌شده / ناقص / انجام‌نشده)
A14: پلتفرم | B14: بازدید / Reach | C14: تعامل (لایک+کامنت+ذخیره) | D14: نرخ تعامل % | E14: کلیک / لینک | F14: پیام ورودی | G14: ذخیره / اشتراک | H14: نکته کیفی | I14: تاریخ ثبت
A15: اینستاگرام | D15: =IF(B15=0,"",IF(B15="","",ROUND(C15/B15*100,1)))
A16: لینکدین | D16: =IF(B16=0,"",IF(B16="","",ROUND(C16/B16*100,1)))
A17: سایت | D17: =IF(B17=0,"",IF(B17="","",ROUND(C17/B17*100,1)))
A18: آپارات | D18: =IF(B18=0,"",IF(B18="","",ROUND(C18/B18*100,1)))
A19: پیامک/ایمیل | D19: =IF(B19=0,"",IF(B19="","",ROUND(C19/B19*100,1)))
A20: سایر | D20: =IF(B20=0,"",IF(B20="","",ROUND(C20/B20*100,1)))
A21: جمع کل | B21: =SUM(B15:B20) -> 0 | C21: =SUM(C15:C20) -> 0 | D21: =IF(B21=0,"",IF(B21="","",ROUND(C21/B21*100,1))) | E21: =SUM(E15:E20) -> 0 | F21: =SUM(F15:F20) -> 0 | G21: =SUM(G15:G20) -> 0

Sheet هفته 5
A1: هفته 5 — پاسخ به اعتراض رایج قیمت
A2: هدف هفته: کاهش اصطکاک فروش با پاسخ شفاف و منطقی به سوال «چرا گران‌تر است؟»
A4: شماره | B4: عنوان کار | C4: نوع محتوا | D4: کانال‌ها | E4: قدم‌ها و جزئیات دقیق اجرا | F4: کپشن / متن پیشنهادی | G4: خروجی مورد انتظار
A5: 1 | B5: پست «چرا نوتوپیا گران‌تر از سررسید معمولی است؟» | C5: پست | D5: اینستاگرام + لینکدین | E5: ساختار: ۱. پذیرش سوال (سوال رایجی است) ۲. سه دلیل ارزش (قابلیت دیجیتال + تجربه هدیه ماندگار + استفاده واقعی بعد از هدیه) ۳. جمع‌بندی: قیمت بالاتر در ازای ارزشی است که سررسید معمولی نمی‌دهد. | F5: سوال رایجی می‌شنویم: چرا نوتوپیا از سررسید معمولی گران‌تر است؟ چون فقط ظاهر یک دفتر را ندارد. نوشته‌ها دیجیتال می‌شوند، تجربه هدیه ماندگارتر است و در نسخه مانا صفحات قابل استفاده مجدد هستند. قیمت، بازتاب ارزش است نه فقط هزینه کاغذ. | G5: ۱ پست پاسخ به اعتراض قیمت
A6: 2 | B6: استوری خلاصه همان پاسخ | C6: استوری | D6: اینستاگرام | E6: ۳ فریم خلاصه همان سه دلیل ارزش | F6: — | G6: استوری ۳ فریمی
A7: 3 | B7: پاسخ استاندارد برای فروشنده در جلسه | C7: متن داخلی | D7: تیم فروش | E7: یک پاسخ ۳۰–۴۵ ثانیه‌ای شفاهی آماده که فروشنده در جلسه استفاده کند. | F7: «قیمت نوتوپیا بالاتر از یک سررسید معمولی است چون علاوه بر کیفیت فیزیکی، قابلیت دیجیتال و در نسخه مانا امکان استفاده مجدد صفحات را دارد. مشتری‌هایی که این تفاوت را می‌بینند، معمولاً آن را به‌عنوان هزینه هدیه خاص می‌پذیرند نه هزینه دفتر.» | G7: ۱ پاسخ استاندارد جلسه
A9: نکات اجرایی هفته: لحن دفاعی نباشد. لحن توضیح ارزش باشد.
A11: 📊 ثبت نتایج و آمار این هفته (بعد از انتشار — حتماً پر شود)
A12: وضعیت اجرا: | C12: (انتخاب کنید: انجام‌شده / ناقص / انجام‌نشده)
A14: پلتفرم | B14: بازدید / Reach | C14: تعامل (لایک+کامنت+ذخیره) | D14: نرخ تعامل % | E14: کلیک / لینک | F14: پیام ورودی | G14: ذخیره / اشتراک | H14: نکته کیفی | I14: تاریخ ثبت
A15: اینستاگرام | D15: =IF(B15=0,"",IF(B15="","",ROUND(C15/B15*100,1)))
A16: لینکدین | D16: =IF(B16=0,"",IF(B16="","",ROUND(C16/B16*100,1)))
A17: سایت | D17: =IF(B17=0,"",IF(B17="","",ROUND(C17/B17*100,1)))
A18: آپارات | D18: =IF(B18=0,"",IF(B18="","",ROUND(C18/B18*100,1)))
A19: پیامک/ایمیل | D19: =IF(B19=0,"",IF(B19="","",ROUND(C19/B19*100,1)))
A20: سایر | D20: =IF(B20=0,"",IF(B20="","",ROUND(C20/B20*100,1)))
A21: جمع کل | B21: =SUM(B15:B20) -> 0 | C21: =SUM(C15:C20) -> 0 | D21: =IF(B21=0,"",IF(B21="","",ROUND(C21/B21*100,1))) | E21: =SUM(E15:E20) -> 0 | F21: =SUM(F15:F20) -> 0 | G21: =SUM(G15:G20) -> 0

Sheet هفته 6
A1: هفته 6 — Case Study شماره ۱ (روایت داخلی)
A2: هدف هفته: ایجاد اعتماد با داستان واقعی از یک سفارش موفق قبلی (بدون نیاز به نقل‌قول مستقیم مشتری).
A4: شماره | B4: عنوان کار | C4: نوع محتوا | D4: کانال‌ها | E4: قدم‌ها و جزئیات دقیق اجرا | F4: کپشن / متن پیشنهادی | G4: خروجی مورد انتظار
A5: 1 | B5: داستان کوتاه Case Study ۱ | C5: پست / کاروسل | D5: اینستاگرام + لینکدین + سایت | E5: قالب اجباری روایت: ۱. مشتری چه نیازی داشت؟ (مثلاً هدیه پایان سال به مشتریان کلیدی) ۲. چرا نوتوپیا انتخاب شد؟ ۳. چه چیزی تحویل شد؟ (تیراژ تقریبی، مدل، شخصی‌سازی در صورت وجود) ۴. چه نتیجه‌ای دیده شد؟ (استفاده واقعی، بازخورد کلی، سفارش بعدی در صورت وجود) نام شرکت را در صورت عدم مجوز می‌توانید کلی نگه دارید (مثلاً «یک شرکت صنعتی»). | F5: یک سازمان صنعتی به دنبال هدیه‌ای بود که هم خاص باشد و هم بعد از تحویل واقعاً استفاده شود. نوتوپیا را انتخاب کردند. نتیجه: هدیه‌ای که روی میز ماند و فراموش نشد. | G5: ۱ Case Study کوتاه
A6: 2 | B6: استوری خلاصه داستان | C6: استوری | D6: اینستاگرام | E6: ۴ فریم: نیاز → انتخاب → تحویل → نتیجه | F6: — | G6: استوری ۴ فریمی
A7: 3 | B7: نسخه کوتاه برای ارسال توسط فروشنده | C7: متن | D7: تیم فروش | E7: نسخه ۶۰–۸۰ کلمه‌ای همان داستان برای ارسال در واتساپ یا ایمیل به فرصت‌های فعال. | F7: — | G7: ۱ متن کوتاه Case Study
A9: نکات اجرایی هفته: Case Study روایت داخلی است. نیاز به تأیید کتبی مشتری ندارد مگر اینکه نام دقیق شرکت ذکر شود.
A11: 📊 ثبت نتایج و آمار این هفته (بعد از انتشار — حتماً پر شود)
A12: وضعیت اجرا: | C12: (انتخاب کنید: انجام‌شده / ناقص / انجام‌نشده)
A14: پلتفرم | B14: بازدید / Reach | C14: تعامل (لایک+کامنت+ذخیره) | D14: نرخ تعامل % | E14: کلیک / لینک | F14: پیام ورودی | G14: ذخیره / اشتراک | H14: نکته کیفی | I14: تاریخ ثبت
A15: اینستاگرام | D15: =IF(B15=0,"",IF(B15="","",ROUND(C15/B15*100,1)))
A16: لینکدین | D16: =IF(B16=0,"",IF(B16="","",ROUND(C16/B16*100,1)))
A17: سایت | D17: =IF(B17=0,"",IF(B17="","",ROUND(C17/B17*100,1)))
A18: آپارات | D18: =IF(B18=0,"",IF(B18="","",ROUND(C18/B18*100,1)))
A19: پیامک/ایمیل | D19: =IF(B19=0,"",IF(B19="","",ROUND(C19/B19*100,1)))
A20: سایر | D20: =IF(B20=0,"",IF(B20="","",ROUND(C20/B20*100,1)))
A21: جمع کل | B21: =SUM(B15:B20) -> 0 | C21: =SUM(C15:C20) -> 0 | D21: =IF(B21=0,"",IF(B21="","",ROUND(C21/B21*100,1))) | E21: =SUM(E15:E20) -> 0 | F21: =SUM(F15:F20) -> 0 | G21: =SUM(G15:G20) -> 0

Sheet هفته 7
A1: هفته 7 — مدل‌های فیزیکی (بخش ۲) + شخصی‌سازی
A2: هدف هفته: پاسخ به سوالات رنگ/جلد/مدل و نشان دادن امکان شخصی‌سازی برای هدیه سازمانی.
A4: شماره | B4: عنوان کار | C4: نوع محتوا | D4: کانال‌ها | E4: قدم‌ها و جزئیات دقیق اجرا | F4: کپشن / متن پیشنهادی | G4: خروجی مورد انتظار
A5: 1 | B5: نمایش تفاوت مدل‌ها + امکان شخصی‌سازی | C5: پست یا ویدئو | D5: اینستاگرام + لینکدین + سایت | E5: • مقایسه کنار هم مدل‌ها • نشان دادن گزینه‌های شخصی‌سازی (لوگو، پیام، رنگ سازمانی در صورت امکان) • اتصال به ارزش هدیه: «هدیه‌ای که با هویت سازمان شما هماهنگ است» | F5: مدل و شخصی‌سازی، بخشی از تجربه هدیه‌ای است که قرار است خاص به نظر برسد. | G5: ۱ پست/ویدئو مدل + شخصی‌سازی
A6: 2 | B6: استوری سوالات رایج مدل | C6: استوری | D6: اینستاگرام | E6: ۲–۳ سوال پرتکرار درباره مدل و شخصی‌سازی + پاسخ خیلی کوتاه | F6: — | G6: استوری سوال و جواب
A7: 3 | B7: چک‌لیست هماهنگی با تولید | C7: داخلی | D7: تیم محتوا + تولید | E7: قبل از انتشار محتوای مدل جدید، تأیید موجودی و قابلیت سفارش از تیم تولید گرفته شود. | F7: — | G7: تأیید هماهنگی
A9: نکات اجرایی هفته: فقط مدل‌هایی را نشان دهید که واقعاً قابل سفارش هستند.
A11: 📊 ثبت نتایج و آمار این هفته (بعد از انتشار — حتماً پر شود)
A12: وضعیت اجرا: | C12: (انتخاب کنید: انجام‌شده / ناقص / انجام‌نشده)
A14: پلتفرم | B14: بازدید / Reach | C14: تعامل (لایک+کامنت+ذخیره) | D14: نرخ تعامل % | E14: کلیک / لینک | F14: پیام ورودی | G14: ذخیره / اشتراک | H14: نکته کیفی | I14: تاریخ ثبت
A15: اینستاگرام | D15: =IF(B15=0,"",IF(B15="","",ROUND(C15/B15*100,1)))
A16: لینکدین | D16: =IF(B16=0,"",IF(B16="","",ROUND(C16/B16*100,1)))
A17: سایت | D17: =IF(B17=0,"",IF(B17="","",ROUND(C17/B17*100,1)))
A18: آپارات | D18: =IF(B18=0,"",IF(B18="","",ROUND(C18/B18*100,1)))
A19: پیامک/ایمیل | D19: =IF(B19=0,"",IF(B19="","",ROUND(C19/B19*100,1)))
A20: سایر | D20: =IF(B20=0,"",IF(B20="","",ROUND(C20/B20*100,1)))
A21: جمع کل | B21: =SUM(B15:B20) -> 0 | C21: =SUM(C15:C20) -> 0 | D21: =IF(B21=0,"",IF(B21="","",ROUND(C21/B21*100,1))) | E21: =SUM(E15:E20) -> 0 | F21: =SUM(F15:F20) -> 0 | G21: =SUM(G15:G20) -> 0

Sheet هفته 8
A1: هفته 8 — هدیه سازمانی چیست و چرا مهم است؟
A2: هدف هفته: آماده‌سازی ذهن مخاطب برای فصل هدیه پایان سال و اتصال نوتوپیا به این موقعیت.
A4: شماره | B4: عنوان کار | C4: نوع محتوا | D4: کانال‌ها | E4: قدم‌ها و جزئیات دقیق اجرا | F4: کپشن / متن پیشنهادی | G4: خروجی مورد انتظار
A5: 1 | B5: محتوای آموزشی حول تجربه گیرنده | C5: پست | D5: اینستاگرام + لینکدین + سایت | E5: تمرکز روی: • هدیه سازمانی فقط «دادن یک چیز» نیست • تجربه گیرنده در لحظه دریافت و هفته‌های بعد مهم است • نوتوپیا چطور این تجربه را بهتر می‌کند | F5: هدیه سازمانی موفق، هدیه‌ای است که بعد از باز شدن هم به کار بیاید و برند شما را یادآوری کند. | G5: ۱ پست آموزشی هدیه سازمانی
A6: 2 | B6: استوری یادآوری فصل هدیه | C6: استوری | D6: اینستاگرام | E6: فریم‌های ملایم درباره نزدیک شدن زمان تصمیم‌گیری هدیه پایان سال | F6: — | G6: استوری یادآوری
A7: 3 | B7: متن کمکی فروش برای شروع گفتگوی هدیه | C7: متن داخلی | D7: تیم فروش | E7: یک متن کوتاه برای شروع گفتگو با مشتریان قبلی یا فرصت‌های گرم درباره هدیه پایان سال. | F7: — | G7: ۱ متن شروع گفتگو
A9: نکات اجرایی هفته: از این هفته به بعد حداقل نیمی از محتوا باید حول هدیه سازمانی و تجربه گیرنده باشد.
A11: 📊 ثبت نتایج و آمار این هفته (بعد از انتشار — حتماً پر شود)
A12: وضعیت اجرا: | C12: (انتخاب کنید: انجام‌شده / ناقص / انجام‌نشده)
A14: پلتفرم | B14: بازدید / Reach | C14: تعامل (لایک+کامنت+ذخیره) | D14: نرخ تعامل % | E14: کلیک / لینک | F14: پیام ورودی | G14: ذخیره / اشتراک | H14: نکته کیفی | I14: تاریخ ثبت
A15: اینستاگرام | D15: =IF(B15=0,"",IF(B15="","",ROUND(C15/B15*100,1)))
A16: لینکدین | D16: =IF(B16=0,"",IF(B16="","",ROUND(C16/B16*100,1)))
A17: سایت | D17: =IF(B17=0,"",IF(B17="","",ROUND(C17/B17*100,1)))
A18: آپارات | D18: =IF(B18=0,"",IF(B18="","",ROUND(C18/B18*100,1)))
A19: پیامک/ایمیل | D19: =IF(B19=0,"",IF(B19="","",ROUND(C19/B19*100,1)))
A20: سایر | D20: =IF(B20=0,"",IF(B20="","",ROUND(C20/B20*100,1)))
A21: جمع کل | B21: =SUM(B15:B20) -> 0 | C21: =SUM(C15:C20) -> 0 | D21: =IF(B21=0,"",IF(B21="","",ROUND(C21/B21*100,1))) | E21: =SUM(E15:E20) -> 0 | F21: =SUM(F15:F20) -> 0 | G21: =SUM(G15:G20) -> 0

Sheet هفته 9
A1: هفته 9 — تجربه گیرنده هدیه
A2: هدف هفته: اتصال احساسی خریدار سازمانی به لحظه دریافت و استفاده هدیه توسط گیرنده نهایی.
A4: شماره | B4: عنوان کار | C4: نوع محتوا | D4: کانال‌ها | E4: قدم‌ها و جزئیات دقیق اجرا | F4: کپشن / متن پیشنهادی | G4: خروجی مورد انتظار
A5: 1 | B5: ویدئو یا پست لحظه دریافت / استفاده | C5: ویدئو یا پست | D5: اینستاگرام + آپارات + لینکدین | E5: اگر ویدئوی واقعی از گیرنده ندارید: • بازسازی ساده با دست و محصول • یا تمرکز روی جزئیات باز کردن و اولین استفاده لحن احساسی ملایم، نه تبلیغاتی تند. | F5: بهترین هدیه، هدیه‌ای است که بعد از باز شدن هم روی میز می‌ماند و استفاده می‌شود. | G5: ۱ ویدئو یا پست تجربه گیرنده
A6: 2 | B6: استوری حس هدیه | C6: استوری | D6: اینستاگرام | E6: فریم‌های کوتاه از حس باز کردن و استفاده اولیه | F6: — | G6: استوری حس هدیه
A7: 3 | B7: نسخه کوتاه برای ارسال به فرصت‌های فعال | C7: متن | D7: تیم فروش | E7: متن کوتاه همراه لینک محتوا برای ارسال به کسانی که در حال بررسی هدیه پایان سال هستند. | F7: — | G7: ۱ متن ارسال
A9: نکات اجرایی هفته: اگر ویدئوی واقعی از مشتری ندارید، بازسازی ساده و صادقانه بهتر از ادعاهای غیرواقعی است.
A11: 📊 ثبت نتایج و آمار این هفته (بعد از انتشار — حتماً پر شود)
A12: وضعیت اجرا: | C12: (انتخاب کنید: انجام‌شده / ناقص / انجام‌نشده)
A14: پلتفرم | B14: بازدید / Reach | C14: تعامل (لایک+کامنت+ذخیره) | D14: نرخ تعامل % | E14: کلیک / لینک | F14: پیام ورودی | G14: ذخیره / اشتراک | H14: نکته کیفی | I14: تاریخ ثبت
A15: اینستاگرام | D15: =IF(B15=0,"",IF(B15="","",ROUND(C15/B15*100,1)))
A16: لینکدین | D16: =IF(B16=0,"",IF(B16="","",ROUND(C16/B16*100,1)))
A17: سایت | D17: =IF(B17=0,"",IF(B17="","",ROUND(C17/B17*100,1)))
A18: آپارات | D18: =IF(B18=0,"",IF(B18="","",ROUND(C18/B18*100,1)))
A19: پیامک/ایمیل | D19: =IF(B19=0,"",IF(B19="","",ROUND(C19/B19*100,1)))
A20: سایر | D20: =IF(B20=0,"",IF(B20="","",ROUND(C20/B20*100,1)))
A21: جمع کل | B21: =SUM(B15:B20) -> 0 | C21: =SUM(C15:C20) -> 0 | D21: =IF(B21=0,"",IF(B21="","",ROUND(C21/B21*100,1))) | E21: =SUM(E15:E20) -> 0 | F21: =SUM(F15:F20) -> 0 | G21: =SUM(G15:G20) -> 0

Sheet هفته 10
A1: هفته 10 — Case Study ۲ + زمان‌بندی خرید
A2: هدف هفته: دومین داستان اعتماد + ایجاد فوریت ملایم برای تصمیم‌گیری در فصل هدیه.
A4: شماره | B4: عنوان کار | C4: نوع محتوا | D4: کانال‌ها | E4: قدم‌ها و جزئیات دقیق اجرا | F4: کپشن / متن پیشنهادی | G4: خروجی مورد انتظار
A5: 1 | B5: Case Study شماره ۲ | C5: پست | D5: اینستاگرام + لینکدین + سایت | E5: همان قالب Case Study ۱ با داستان متفاوت (ترجیحاً صنعت یا کاربرد دیگر). | F5: — | G5: ۱ Case Study دوم
A6: 2 | B6: یادآوری پنجره زمانی پایان سال | C6: پست یا استوری | D6: اینستاگرام + لینکدین | E6: یادآوری محترمانه که تصمیم‌گیری و تولید/تحویل زمان می‌برد و پنجره زمانی محدود است. بدون فشار فروش تند. | F6: برای هدیه پایان سال، تصمیم‌گیری زودتر = انتخاب بهتر و تحویل به‌موقع. | G6: ۱ محتوای زمان‌بندی
A7: 3 | B7: متن پیگیری برای فرصت‌های فعال | C7: متن داخلی | D7: تیم فروش | E7: متن کوتاه پیگیری با اشاره به محدودیت زمانی تولید/تحویل. | F7: — | G7: ۱ متن پیگیری
A9: نکات اجرایی هفته: فوریت باید واقعی و محترمانه باشد، نه ساختگی.
A11: 📊 ثبت نتایج و آمار این هفته (بعد از انتشار — حتماً پر شود)
A12: وضعیت اجرا: | C12: (انتخاب کنید: انجام‌شده / ناقص / انجام‌نشده)
A14: پلتفرم | B14: بازدید / Reach | C14: تعامل (لایک+کامنت+ذخیره) | D14: نرخ تعامل % | E14: کلیک / لینک | F14: پیام ورودی | G14: ذخیره / اشتراک | H14: نکته کیفی | I14: تاریخ ثبت
A15: اینستاگرام | D15: =IF(B15=0,"",IF(B15="","",ROUND(C15/B15*100,1)))
A16: لینکدین | D16: =IF(B16=0,"",IF(B16="","",ROUND(C16/B16*100,1)))
A17: سایت | D17: =IF(B17=0,"",IF(B17="","",ROUND(C17/B17*100,1)))
A18: آپارات | D18: =IF(B18=0,"",IF(B18="","",ROUND(C18/B18*100,1)))
A19: پیامک/ایمیل | D19: =IF(B19=0,"",IF(B19="","",ROUND(C19/B19*100,1)))
A20: سایر | D20: =IF(B20=0,"",IF(B20="","",ROUND(C20/B20*100,1)))
A21: جمع کل | B21: =SUM(B15:B20) -> 0 | C21: =SUM(C15:C20) -> 0 | D21: =IF(B21=0,"",IF(B21="","",ROUND(C21/B21*100,1))) | E21: =SUM(E15:E20) -> 0 | F21: =SUM(F15:F20) -> 0 | G21: =SUM(G15:G20) -> 0

Sheet هفته 11
A1: هفته 11 — پاسخ به اعتراض زمان تحویل و تیراژ
A2: هدف هفته: بستن دو اعتراض متداول فصل هدیه با پاسخ شفاف و هماهنگ با تولید.
A4: شماره | B4: عنوان کار | C4: نوع محتوا | D4: کانال‌ها | E4: قدم‌ها و جزئیات دقیق اجرا | F4: کپشن / متن پیشنهادی | G4: خروجی مورد انتظار
A5: 1 | B5: پست پاسخ به اعتراض زمان تحویل و تیراژ | C5: پست | D5: اینستاگرام + لینکدین | E5: دو بخش جدا یا یک کاروسل: بخش ۱: زمان تحویل — چه عواملی روی زمان اثر می‌گذارد و چطور می‌توان برنامه‌ریزی کرد. بخش ۲: تیراژ — حداقل/حداکثر منطقی و انعطاف در سفارش‌های سازمانی. اعداد دقیق را فقط بعد از هماهنگی با تولید بنویسید. | F5: دو سوال پرتکرار در فصل هدیه: زمان تحویل چقدر است و تیراژ چطور کار می‌کند؟ پاسخ شفاف، برنامه‌ریزی را آسان‌تر می‌کند. | G5: ۱ پست
A6: 2 | B6: استوری | C6: استوری | D6: اینستاگرام | E6: فریم ۱: «سوال رایج: تحویل چقدر طول می‌کشد؟» فریم‌های بعدی: پاسخ خلاصه + دعوت به هماهنگی زودتر | F6: — | G6: استوری ۴ فریمی
A7: 3 | B7: پاسخ استاندارد برای فروش | C7: متن داخلی | D7: تیم فروش | E7: دو پاسخ کوتاه و استاندارد برای اعتراض زمان تحویل و تیراژ (هماهنگ با واقعیت تولید). | F7: — | G7: ۲ پاسخ استاندارد
A9: نکات اجرایی هفته: قبل از انتشار، با تیم تولید و فروش هماهنگ کنید که اعداد و بازه‌های زمانی صحیح باشند.
A11: 📊 ثبت نتایج و آمار این هفته (بعد از انتشار — حتماً پر شود)
A12: وضعیت اجرا: | C12: (انتخاب کنید: انجام‌شده / ناقص / انجام‌نشده)
A14: پلتفرم | B14: بازدید / Reach | C14: تعامل (لایک+کامنت+ذخیره) | D14: نرخ تعامل % | E14: کلیک / لینک | F14: پیام ورودی | G14: ذخیره / اشتراک | H14: نکته کیفی | I14: تاریخ ثبت
A15: اینستاگرام | D15: =IF(B15=0,"",IF(B15="","",ROUND(C15/B15*100,1)))
A16: لینکدین | D16: =IF(B16=0,"",IF(B16="","",ROUND(C16/B16*100,1)))
A17: سایت | D17: =IF(B17=0,"",IF(B17="","",ROUND(C17/B17*100,1)))
A18: آپارات | D18: =IF(B18=0,"",IF(B18="","",ROUND(C18/B18*100,1)))
A19: پیامک/ایمیل | D19: =IF(B19=0,"",IF(B19="","",ROUND(C19/B19*100,1)))
A20: سایر | D20: =IF(B20=0,"",IF(B20="","",ROUND(C20/B20*100,1)))
A21: جمع کل | B21: =SUM(B15:B20) -> 0 | C21: =SUM(C15:C20) -> 0 | D21: =IF(B21=0,"",IF(B21="","",ROUND(C21/B21*100,1))) | E21: =SUM(E15:E20) -> 0 | F21: =SUM(F15:F20) -> 0 | G21: =SUM(G15:G20) -> 0

Sheet هفته 12
A1: هفته 12 — جمع‌بندی + دعوت ملایم
A2: هدف هفته: دوره ۳ ماهه با وضوح ارزش‌ها بسته شود و دعوت غیر فشاری برای بررسی نوتوپیا به‌عنوان گزینه هدیه ارائه گردد.
A4: شماره | B4: عنوان کار | C4: نوع محتوا | D4: کانال‌ها | E4: قدم‌ها و جزئیات دقیق اجرا | F4: کپشن / متن پیشنهادی | G4: خروجی مورد انتظار
A5: 1 | B5: پست جمع‌بندی ارزش‌های نوتوپیا | C5: پست کاروسل | D5: اینستاگرام + لینکدین + سایت | E5: اسلایدها: ۱. نوتوپیا به چه دردی می‌خورد؟ ۲. چطور کار می‌کند؟ ۳. چه فرقی با معمولی دارد؟ ۴. مدل‌ها و شخصی‌سازی ۵. دعوت ملایم: «اگر برای هدیه سازمانی امسال در حال بررسی هستید، خوشحال می‌شویم گفتگو کنیم.» | F5: در ۱۲ هفته گذشته تلاش کردیم شفاف بگوییم نوتوپیا چیست، به چه دردی می‌خورد و چرا برای هدیه سازمانی گزینه متفاوتی است. اگر در حال بررسی هستید، مسیر گفتگو باز است. | G5: ۱ پست جمع‌بندی
A6: 2 | B6: استوری پایانی | C6: استوری | D6: اینستاگرام | E6: فریم ۱: «۱۲ هفته صحبت کردیم» فریم ۲: «از کاربرد تا تجربه گیرنده» فریم ۳: «اگر سوالی دارید یا در حال بررسی هستید، در پیام مستقیم بپرسید» | F6: — | G6: استوری ۳ فریمی
A7: 3 | B7: گزارش داخلی ۳ ماهه برای مدیریت | C7: گزارش | D7: داخلی | E7: خلاصه کارهای انجام‌شده، دارایی‌های ساخته‌شده (Case Study، ویدئوها، پاسخ اعتراض‌ها)، آمار کلی و پیشنهاد قدم بعدی. | F7: — | G7: ۱ گزارش کوتاه داخلی
A9: نکات اجرایی هفته: لحن فروش مستقیم و فشاری نباشد. این کار جمع‌بندی دوره است نه کمپین فروش تند.
A11: 📊 ثبت نتایج و آمار این هفته (بعد از انتشار — حتماً پر شود)
A12: وضعیت اجرا: | C12: (انتخاب کنید: انجام‌شده / ناقص / انجام‌نشده)
A14: پلتفرم | B14: بازدید / Reach | C14: تعامل (لایک+کامنت+ذخیره) | D14: نرخ تعامل % | E14: کلیک / لینک | F14: پیام ورودی | G14: ذخیره / اشتراک | H14: نکته کیفی | I14: تاریخ ثبت
A15: اینستاگرام | D15: =IF(B15=0,"",IF(B15="","",ROUND(C15/B15*100,1)))
A16: لینکدین | D16: =IF(B16=0,"",IF(B16="","",ROUND(C16/B16*100,1)))
A17: سایت | D17: =IF(B17=0,"",IF(B17="","",ROUND(C17/B17*100,1)))
A18: آپارات | D18: =IF(B18=0,"",IF(B18="","",ROUND(C18/B18*100,1)))
A19: پیامک/ایمیل | D19: =IF(B19=0,"",IF(B19="","",ROUND(C19/B19*100,1)))
A20: سایر | D20: =IF(B20=0,"",IF(B20="","",ROUND(C20/B20*100,1)))
A21: جمع کل | B21: =SUM(B15:B20) -> 0 | C21: =SUM(C15:C20) -> 0 | D21: =IF(B21=0,"",IF(B21="","",ROUND(C21/B21*100,1))) | E21: =SUM(E15:E20) -> 0 | F21: =SUM(F15:F20) -> 0 | G21: =SUM(G15:G20) -> 0
